Workbook
Name Material: [1]ZMV044!$D$2:$D$7000

Sheet NG list
C1: NG&Deadstock | D1: IAF19567 | E1: Shortage | F1: IAF19566 | L1: Vendor cost | N1: PSNV cost | P1: Pending | R1: Scrap cost | S1: PIC remark status | T1: Maker | U1: Deadline | V1: Description | W1: PIC | X1: PCB | Y1: VENDOR CODE | Z1: VENDOR NAME | AA1: PSNV req
A2: Plan | B2: Plnt | C2: MTyp | D2: Material | E2: Material description | F2: Standard price | G2: SLoc | H2: Total stock qty | I2: Total stock amount | J2: Pur grp | K2: MRP ctl | L2: Q.ty | M2: Amount | N2: Q.ty | O2: Amount | P2: Q.ty | Q2: Amount | AA2: Oct | AB2: Nov | AC2: Dec | AD2: Jan | AE2: PUS | AF2: & | AG2: Actual Price | AH2: Debit Note number
A3: DP | B3: VR01 | C3: ROH | D3: PNBC1678ZA1MA15/V1 | E3: KEY/METAL/BUTTON COVER V530 | F3: 1.3877 | G3: 1185 | H3: 6 | I3: 8.3262 | J3: R35 | K3: R35 | N3: 6 | O3: =N3*F3 -> 8.3262 | R3: PSNV cost | S3: Scrap PSNV cost 2pcs | V3: Painting NG | W3: Thùy Linh | Y3: VE053 | Z3: TSUKUBA DIECASTING VIETNAM CO. LTD | AA3: -660 | AB3: -528 | AC3: -492 | AD3: -486 | AE3: Local | AF3: =D3&G3 -> PNBC1678ZA1MA15/V11185
A4: DP | B4: VR01 | C4: ROH | D4: PNPN1591ZA/V2 | E4: CARTON PAD | F4: 0.1485 | G4: 1185 | H4: 55 | I4: 8.1675 | J4: R44 | K4: R44 | N4: 55 | O4: =N4*F4 -> 8.1675 | R4: PSNV cost | S4: Scrap PSNV cost | W4: Nguyễn | Y4: VE061 | Z4: HUNG YEN CHUNG PHAT CO. LTD | AA4: -4473 | AB4: -4758 | AC4: -4920 | AD4: -4350 | AE4: Local | AF4: =D4&G4 -> PNPN1591ZA/V21185
A5: DP | B5: VR01 | C5: ROH | D5: PNMY1005ZA-VU | E5: CHARGER SHEET | F5: 0.0665 | G5: 1185 | H5: 79 | I5: 5.2535 | J5: R96 | K5: R33 | N5: 79 | O5: =N5*F5 -> 5.2535 | R5: PSNV cost | S5: Scrap PSNV cost | W5: Hà My | Y5: VE011 | Z5: MALUGO VIETNAM CO. LTD | AA5: -50 | AB5: -30 | AC5: -20 | AD5: 0 | AE5: Local | AF5: =D5&G5 -> PNMY1005ZA-VU1185
A6: DP | B6: VR01 | C6: ROH | D6: PNPK4298006ZA/V1 | E6: CARTON BOX | F6: 0.22213 | G6: 1185 | H6: 21 | I6: 4.66473 | J6: R44 | K6: R44 | N6: 21 | O6: =N6*F6 -> 4.66473 | R6: PSNV cost | S6: Scrap PSNV cost | W6: Nguyễn | Y6: VE041 | Z6: DYNAPAC (HANOI) CO. LTD | AA6: -1800 | AB6: -1506 | AC6: -1410 | AD6: -1320 | AE6: Local | AF6: =D6&G6 -> PNPK4298006ZA/V11185
A7: DP | B7: VR01 | C7: ROH | D7: PNPK4313002ZA/V1 | E7: CARTON BOX | F7: 0.2283 | G7: 1185 | H7: 18 | I7: 4.1094 | J7: R44 | K7: R44 | N7: 18 | O7: =N7*F7 -> 4.1094 | R7: PSNV cost | S7: Scrap PSNV cost | W7: Nguyễn | Y7: VE116 | Z7: BRANCH OF OJITEX HAI PHONG CO. | AA7: -3189 | AB7: -2352 | AC7: 0 | AD7: -450 | AE7: Local | AF7: =D7&G7 -> PNPK4313002ZA/V11185
A8: DP | B8: VR01 | C8: ROH | D8: PNGP1866ZA1KC15/V1 | E8: PANEL/Plastic/FRONT PANEL | F8: 0.40015 | G8: 1185 | H8: 10 | I8: 4.0015 | J8: R35 | K8: R35 | N8: 10 | O8: =N8*F8 -> 4.0015 | R8: PSNV cost | S8: Scrap PSNV cost | W8: Thùy Linh | Y8: VE079 | Z8: VIETDRAGON PRECISION PLASTIC CO. | AA8: -34213 | AB8: -45108 | AC8: -20820 | AD8: -40740 | AE8: Local | AF8: =D8&G8 -> PNGP1866ZA1KC15/V11185
A9: DP | B9: VR01 | C9: ROH | D9: PNPG3443005YA/V1 | E9: CARTON BOX | F9: 0.7653 | G9: 1185 | H9: 5 | I9: 3.8265 | J9: R44 | K9: R44 | N9: 5 | O9: =N9*F9 -> 3.8265 | R9: PSNV cost | S9: Scrap PSNV cost | W9: Nguyễn | Y9: VE116 | Z9: BRANCH OF OJITEX HAI PHONG CO. | AA9: -640 | AB9: -551 | AC9: -450 | AD9: -400 | AE9: Local | AF9: =D9&G9 -> PNPG3443005YA/V11185
A10: DP | B10: VR01 | C10: ROH | D10: PNPN1580ZA/V1 | E10: INNER PAD / SZ50 | F10: 0.14862 | G10: 1185 | H10: 25 | I10: 3.7155 | J10: R44 | K10: R44 | N10: 25 | O10: =N10*F10 -> 3.7155 | R10: PSNV cost | S10: Scrap PSNV cost | V10: Torn | W10: Nguyễn | Y10: VE041 | Z10: DYNAPAC (HANOI) CO. LTD | AA10: -6534 | AB10: -5328 | AC10: -4392 | AD10: -3324 | AE10: Local | AF10: =D10&G10 -> PNPN1580ZA/V11185
A11: DP | B11: VR01 | C11: ROH | D11: PNPK4370001ZA/V1 | E11: INNER BOX | F11: 0.16454 | G11: 1185 | H11: 21 | I11: 3.45534 | J11: R44 | K11: R44 | N11: 21 | O11: =N11*F11 -> 3.45534 | R11: PSNV cost | S11: Scrap PSNV cost | W11: Nguyễn | Y11: VE041 | Z11: DYNAPAC (HANOI) CO. LTD | AA11: -9960 | AB11: -9780 | AC11: -7050 | AD11: -9000 | AE11: Local | AF11: =D11&G11 -> PNPK4370001ZA/V11185
A12: DP | B12: VR01 | C12: ROH | D12: PNPK3396001YA/V1 | E12: CARTON BOX | F12: 0.2413 | G12: 1185 | H12: 13 | I12: 3.1369 | J12: R44 | K12: R44 | N12: 13 | O12: =N12*F12 -> 3.1369 | R12: PSNV cost | S12: Scrap PSNV cost | W12: Nguyễn | Y12: VE116 | Z12: BRANCH OF OJITEX HAI PHONG CO. | AA12: -360 | AB12: -330 | AC12: -330 | AD12: -300 | AE12: Local | AF12: =D12&G12 -> PNPK3396001YA/V11185
A13: DP | B13: VR01 | C13: ROH | D13: PNPK4206001YA/V1 | E13: CARTON BOX | F13: 0.26932 | G13: 1185 | H13: 11 | I13: 2.96252 | J13: R44 | K13: R44 | N13: 11 | O13: =N13*F13 -> 2.96252 | R13: PSNV cost | S13: Scrap PSNV cost | W13: Nguyễn | Y13: VE041 | Z13: DYNAPAC (HANOI) CO. LTD | AA13: -2820 | AB13: -1409 | AC13: -1830 | AD13: -1950 | AE13: Local | AF13: =D13&G13 -> PNPK4206001YA/V11185
A14: DP | B14: VR01 | C14: ROH | D14: PNPK4338008ZA/V1 | E14: CARTON BOX | F14: 0.10167 | G14: 1185 | H14: 29 | I14: 2.94843 | J14: R31 | K14: R31 | N14: 29 | O14: =N14*F14 -> 2.94843 | R14: PSNV cost | S14: Scrap PSNV cost | V14: Torn | W14: Đặng Huyền | Y14: VE115 | Z14: PHUONG LINH INVESTMENT TRADING | AA14: -6900 | AB14: -10404 | AC14: -1746 | AD14: -6240 | AE14: Local | AF14: =D14&G14 -> PNPK4338008ZA/V11185
A15: DP | B15: VR01 | C15: ROH | D15: PNPK4298005ZA/V1 | E15: CARTON BOX | F15: 0.21426 | G15: 1185 | H15: 13 | I15: 2.78538 | J15: R44 | K15: R44 | N15: 13 | O15: =N15*F15 -> 2.78538 | R15: PSNV cost | S15: Scrap PSNV cost | T15: =IFERROR(VLOOKUP(D15,[2]Sheet1!$B:$C,2,0),"") | W15: Nguyễn | Y15: VE041 | Z15: DYNAPAC (HANOI) CO. LTD | AA15: -1050 | AB15: -918 | AC15: -900 | AD15: -810 | AE15: Local | AF15: =D15&G15 -> PNPK4298005ZA/V11185
A16: DP | B16: VR01 | C16: ROH | D16: PNPK4241007ZA/V2 | E16: CARTON BOX | F16: 0.25961 | G16: 1185 | H16: 10 | I16: 2.5961 | J16: R44 | K16: R44 | N16: 10 | O16: =N16*F16 -> 2.5961 | R16: PSNV cost | S16: Scrap PSNV cost | T16: =IFERROR(VLOOKUP(D16,[2]Sheet1!$B:$C,2,0),"") | W16: Nguyễn | Y16: VE041 | Z16: DYNAPAC (HANOI) CO. LTD | AA16: -1440 | AB16: -1266 | AC16: -1560 | AD16: -1500 | AE16: Local | AF16: =D16&G16 -> PNPK4241007ZA/V21185
A17: DP | B17: VR01 | C17: ROH | D17: PNPK3673004YA/V1 | E17: CARTON BOX | F17: 0.424 | G17: 1185 | H17: 6 | I17: 2.544 | J17: R44 | K17: R44 | N17: 6 | O17: =N17*F17 -> 2.544 | R17: PSNV cost | S17: Scrap PSNV cost | W17: Nguyễn | Y17: VE116 | Z17: BRANCH OF OJITEX HAI PHONG CO. | AA17: -750 | AB17: -1224 | AC17: -750 | AD17: -870 | AE17: Local | AF17: =D17&G17 -> PNPK3673004YA/V11185
A18: DP | B18: VR01 | C18: ROH | D18: PNPK3396008ZA/V1 | E18: CARTON BOX | F18: 0.2783 | G18: 1185 | H18: 9 | I18: 2.5047 | J18: R44 | K18: R44 | N18: 9 | O18: =N18*F18 -> 2.5047 | R18: PSNV cost | S18: Scrap PSNV cost | W18: Nguyễn | Y18: VE116 | Z18: BRANCH OF OJITEX HAI PHONG CO. | AA18: -300 | AB18: -300 | AC18: -282 | AD18: -270 | AE18: Local | AF18: =D18&G18 -> PNPK3396008ZA/V11185
A19: DP | B19: VR01 | C19: ROH | D19: PNPK3395008YA/V1 | E19: CARTON BOX | F19: 0.3098 | G19: 1185 | H19: 8 | I19: 2.4784 | J19: R44 | K19: R44 | N19: 8 | O19: =N19*F19 -> 2.4784 | R19: PSNV cost | S19: Scrap PSNV cost | W19: Nguyễn | Y19: VE116 | Z19: BRANCH OF OJITEX HAI PHONG CO. | AA19: -690 | AB19: -690 | AC19: -582 | AD19: -540 | AE19: Local | AF19: =D19&G19 -> PNPK3395008YA/V11185
A20: DP | B20: VR01 | C20: ROH | D20: PNGE1086ZA/V1 | E20: PANEL/METAL/BUTTON PLATE/VH558 | F20: 1.17 | G20: 1185 | H20: 2 | I20: 2.34 | J20: R30 | K20: R30 | N20: 2 | O20: =N20*F20 -> 2.34 | R20: PSNV cost | S20: Scrap PSNV cost | T20: =IFERROR(VLOOKUP(D20,[2]Sheet1!$B:$C,2,0),"") | W20: Tâm | Y20: VE075 | Z20: SHINEI CORONA VIETNAM CO. LTD | AA20: -1419 | AB20: -1185 | AC20: -1179 | AD20: -1698 | AE20: Local | AF20: =D20&G20 -> PNGE1086ZA/V11185
A21: DP | B21: VR01 | C21: ROH | D21: PNPK4167003ZA/V3 | E21: CARTON BOX | F21: 0.22266 | G21: 1185 | H21: 10 | I21: 2.2266 | J21: R44 | K21: R44 | N21: 10 | O21: =N21*F21 -> 2.2266 | R21: PSNV cost | S21: Scrap PSNV cost | W21: Nguyễn | Y21: VE041 | Z21: DYNAPAC (HANOI) CO. LTD | AA21: -1173 | AB21: -1440 | AC21: -1710 | AD21: -1200 | AE21: Local | AF21: =D21&G21 -> PNPK4167003ZA/V31185
A22: DP | B22: VR01 | C22: ROH | D22: PNPK3396007YA/V1 | E22: CARTON BOX | F22: 0.2441 | G22: 1185 | H22: 9 | I22: 2.1969 | J22: R44 | K22: R44 | N22: 9 | O22: =N22*F22 -> 2.1969 | R22: PSNV cost | S22: Scrap PSNV cost | W22: Nguyễn | Y22: VE116 | Z22: BRANCH OF OJITEX HAI PHONG CO. | AA22: -318 | AB22: -300 | AC22: -312 | AD22: -270 | AE22: Local | AF22: =D22&G22 -> PNPK3396007YA/V11185
A23: DP | B23: VR01 | C23: ROH | D23: PNPK4298008ZA/V1 | E23: CARTON BOX | F23: 0.23447 | G23: 1185 | H23: 9 | I23: 2.11023 | J23: R44 | K23: R44 | N23: 9 | O23: =N23*F23 -> 2.11023 | R23: PSNV cost | S23: Scrap PSNV cost | W23: Nguyễn | Y23: VE041 | Z23: DYNAPAC (HANOI) CO. LTD | AA23: -5100 | AB23: -5430 | AC23: -2490 | AD23: -3432 | AE23: Local | AF23: =D23&G23 -> PNPK4298008ZA/V11185
A24: DP | B24: VR01 | C24: ROH | D24: PNPK3575002YA/V1 | E24: CARTON BOX | F24: 0.3505 | G24: 1185 | H24: 6 | I24: 2.103 | J24: R44 | K24: R44 | N24: 6 | O24: =N24*F24 -> 2.103 | R24: PSNV cost | S24: Scrap PSNV cost | T24: =IFERROR(VLOOKUP(D24,[2]Sheet1!$B:$C,2,0),"") | W24: Nguyễn | Y24: VE116 | Z24: BRANCH OF OJITEX HAI PHONG CO. | AA24: -900 | AB24: -912 | AC24: -810 | AD24: -780 | AE24: Local | AF24: =D24&G24 -> PNPK3575002YA/V11185
A25: DP | B25: VR01 | C25: ROH | D25: PNPG4047004ZA/V1 | E25: Carton box | F25: 0.32458 | G25: 1185 | H25: 6 | I25: 1.94748 | J25: R31 | K25: R31 | N25: 6 | O25: =N25*F25 -> 1.94748 | R25: PSNV cost | S25: Scrap PSNV cost | W25: Đặng Huyền | Y25: VE115 | Z25: PHUONG LINH INVESTMENT TRADING | AA25: -958 | AB25: -907 | AC25: -880 | AD25: -858 | AE25: Local | AF25: =D25&G25 -> PNPG4047004ZA/V11185
A26: DP | B26: VR01 | C26: ROH | D26: PNPK3395010ZA/V1 | E26: CARTON BOX | F26: 0.6274 | G26: 1185 | H26: 3 | I26: 1.8822 | J26: R44 | K26: R44 | N26: 3 | O26: =N26*F26 -> 1.8822 | R26: PSNV cost | S26: Scrap PSNV cost | W26: Nguyễn | Y26: VE116 | Z26: BRANCH OF OJITEX HAI PHONG CO. | AA26: -420 | AB26: -342 | AC26: -360 | AD26: -270 | AE26: Local | AF26: =D26&G26 -> PNPK3395010ZA/V11185
A27: DP | B27: VR01 | C27: ROH | D27: PNPN1593ZA/V2 | E27: PAD/EPS/HC400 | F27: 0.59 | G27: 1185 | H27: 3 | I27: 1.77 | J27: R35 | K27: R35 | N27: 3 | O27: =N27*F27 -> 1.77 | R27: PSNV cost | S27: Scrap PSNV cost | W27: Thùy Linh | Y27: VE090 | Z27: THIEN QUANG GROUP JOINT STOCK | AA27: -270 | AB27: -282 | AC27: -330 | AD27: -360 | AE27: Local | AF27: =D27&G27 -> PNPN1593ZA/V21185
A28: DP | B28: VR01 | C28: ROH | D28: PNPK4361004ZA/V1 | E28: Carton box | F28: 0.1172 | G28: 1185 | H28: 15 | I28: 1.758 | J28: R31 | K28: R31 | N28: 15 | O28: =N28*F28 -> 1.758 | R28: PSNV cost | S28: Scrap PSNV cost | V28: Torn | W28: Đặng Huyền | Y28: VE115 | Z28: PHUONG LINH INVESTMENT TRADING | AA28: -5700 | AB28: -5412 | AC28: -5250 | AD28: -5100 | AE28: Local | AF28: =D28&G28 -> PNPK4361004ZA/V11185
A29: DP | B29: VR01 | C29: ROH | D29: PNKE1264ZB/V2 | E29: JOINT REAR COVER/CAMERA | F29: 1.6853 | G29: 1185 | H29: 1 | I29: 1.6853 | J29: R35 | K29: R35 | N29: 1 | O29: =N29*F29 -> 1.6853 | R29: PSNV cost | S29: Scrap PSNV cost | T29: =IFERROR(VLOOKUP(D29,[2]Sheet1!$B:$C,2,0),"") | W29: Thùy Linh | Y29: VE053 | Z29: TSUKUBA DIECASTING VIETNAM CO. LTD | AA29: -2670 | AB29: -2877 | AC29: -2100 | AD29: -2070 | AE29: Local | AF29: =D29&G29 -> PNKE1264ZB/V21185
A30: DP | B30: VR01 | C30: ROH | D30: PNPN1622ZA/V1 | E30: CARTON PAD | F30: 0.0918 | G30: 1185 | H30: 18 | I30: 1.6524 | J30: R44 | K30: R44 | N30: 18 | O30: =N30*F30 -> 1.6524 | R30: PSNV cost | S30: Scrap PSNV cost | T30: =IFERROR(VLOOKUP(D30,[2]Sheet1!$B:$C,2,0),"") | W30: Nguyễn | Y30: VE061 | Z30: HUNG YEN CHUNG PHAT CO. LTD | AA30: 0 | AB30: 0 | AC30: 0 | AD30: 0 | AE30: Local | AF30: =D30&G30 -> PNPN1622ZA/V11185
A31: DP | B31: VR01 | C31: ROH | D31: PNPK4338009ZA/V1 | E31: CARTON BOX | F31: 0.10208 | G31: 1185 | H31: 16 | I31: 1.63328 | J31: R31 | K31: R31 | N31: 16 | O31: =N31*F31 -> 1.63328 | R31: PSNV cost | S31: Scrap PSNV cost | T31: =IFERROR(VLOOKUP(D31,[2]Sheet1!$B:$C,2,0),"") | W31: Đặng Huyền | Y31: VE115 | Z31: PHUONG LINH INVESTMENT TRADING | AA31: -5100 | AB31: -6102 | AC31: -3348 | AD31: -4350 | AE31: Local | AF31: =D31&G31 -> PNPK4338009ZA/V11185
A32: DP | B32: VR01 | C32: ROH | D32: PNGP1419ZA/V1 | E32: FRONT PANEL METAL | F32: 1.57404 | G32: 1185 | H32: 1 | I32: 1.57404 | J32: R97 | K32: R30 | N32: 1 | O32: =N32*F32 -> 1.57404 | R32: PSNV cost | S32: Scrap PSNV cost | T32: =IFERROR(VLOOKUP(D32,[2]Sheet1!$B:$C,2,0),"") | W32: Tâm | Y32: VE075 | Z32: SHINEI CORONA VIETNAM CO. LTD | AA32: -23 | AB32: 0 | AC32: 0 | AD32: 0 | AE32: Local | AF32: =D32&G32 -> PNGP1419ZA/V11185
A33: DP | B33: VR01 | C33: ROH | D33: PNPK3799005YA/V1 | E33: CARTON BOX | F33: 0.3664 | G33: 1185 | H33: 4 | I33: 1.4656 | J33: R44 | K33: R44 | N33: 4 | O33: =N33*F33 -> 1.4656 | R33: PSNV cost | S33: Scrap PSNV cost | W33: Nguyễn | Y33: VE116 | Z33: BRANCH OF OJITEX HAI PHONG CO. | AA33: -300 | AB33: -282 | AC33: -312 | AD33: -270 | AE33: Local | AF33: =D33&G33 -> PNPK3799005YA/V11185
A34: DP | B34: VR01 | C34: ROH | D34: PNPN1624ZA/V1 | E34: CARTON PAD | F34: 0.0708 | G34: 1185 | H34: 18 | I34: 1.2744 | J34: R44 | K34: R44 | N34: 18 | O34: =N34*F34 -> 1.2744 | R34: PSNV cost | S34: Scrap PSNV cost | T34: =IFERROR(VLOOKUP(D34,[2]Sheet1!$B:$C,2,0),"") | W34: Nguyễn | Y34: VE061 | Z34: HUNG YEN CHUNG PHAT CO. LTD | AA34: -12342 | AB34: -12846 | AC34: -9804 | AD34: -10164 | AE34: Local | AF34: =D34&G34 -> PNPN1624ZA/V11185
A35: DP | B35: VR01 | C35: ROH | D35: PNPK4313004ZA/V1 | E35: CARTON BOX | F35: 0.2542 | G35: 1185 | H35: 5 | I35: 1.271 | J35: R44 | K35: R44 | N35: 5 | O35: =N35*F35 -> 1.271 | R35: PSNV cost | S35: Scrap PSNV cost | W35: Nguyễn | Y35: VE116 | Z35: BRANCH OF OJITEX HAI PHONG CO. | AA35: -450 | AB35: -1146 | AC35: -480 | AD35: -348 | AE35: Local | AF35: =D35&G35 -> PNPK4313004ZA/V11185
A36: DP | B36: VR01 | C36: ROH | D36: PNPK4361006ZA/V1 | E36: Carton box | F36: 0.15592 | G36: 1185 | H36: 8 | I36: 1.24736 | J36: R31 | K36: R31 | N36: 8 | O36: =N36*F36 -> 1.24736 | R36: PSNV cost | S36: Scrap PSNV cost | W36: Đặng Huyền | Y36: VE115 | Z36: PHUONG LINH INVESTMENT TRADING | AA36: -2524 | AB36: -2238 | AC36: -2490 | AD36: -2220 | AE36: Local | AF36: =D36&G36 -> PNPK4361006ZA/V11185
A37: DP | B37: VR01 | C37: ROH | D37: PFYP1019ZE | E37: PLATE/FRONT | F37: 0.4149 | G37: 1185 | H37: 3 | I37: 1.2447 | J37: R35 | K37: R35 | N37: 3 | O37: =N37*F37 -> 1.2447 | R37: PSNV cost | S37: Scrap PSNV cost | T37: =IFERROR(VLOOKUP(D37,[2]Sheet1!$B:$C,2,0),"") | W37: Thùy Linh | Y37: VE079 | Z37: VIETDRAGON PRECISION PLASTIC CO. | AA37: -2077 | AB37: -648 | AC37: -1592 | AD37: -1569 | AE37: Local | AF37: =D37&G37 -> PFYP1019ZE1185
A38: DP | B38: VR01 | C38: ROH | D38: PNMH1262ZB/V2 | E38: GEAR STOPPER/ARM | F38: 1.198 | G38: 1185 | H38: 1 | I38: 1.198 | J38: R35 | K38: R35 | N38: 1 | O38: =N38*F38 -> 1.198 | R38: PSNV cost | S38: Scrap PSNV cost | T38: =IFERROR(VLOOKUP(D38,[2]Sheet1!$B:$C,2,0),"") | W38: Thùy Linh | Y38: VE053 | Z38: TSUKUBA DIECASTING VIETNAM CO. LTD | AA38: -2670 | AB38: -2877 | AC38: -2100 | AD38: -2070 | AE38: Local | AF38: =D38&G38 -> PNMH1262ZB/V21185
A39: DP | B39: VR01 | C39: ROH | D39: PNPN1550ZA/V3 | E39: CARTON PAD | F39: 0.12188 | G39: 1185 | H39: 9 | I39: 1.09692 | J39: R44 | K39: R44 | N39: 9 | O39: =N39*F39 -> 1.09692 | R39: PSNV cost | S39: Scrap PSNV cost | W39: Nguyễn | Y39: VE041 | Z39: DYNAPAC (HANOI) CO. LTD | AA39: -1101 | AB39: 0 | AC39: -900 | AD39: -900 | AE39: Local | AF39: =D39&G39 -> PNPN1550ZA/V31185
A40: DP | B40: VR01 | C40: ROH | D40: PNHX2299ZA/V1 | E40: SHEET/SPEAKER/V572A | F40: 0.098 | G40: 1185 | H40: 11 | I40: 1.078 | J40: R33 | K40: R33 | N40: 11 | O40: =N40*F40 -> 1.078 | R40: PSNV cost | S40: Scrap PSNV cost | W40: Hà My | Y40: VE054 | Z40: FIT VIETNAM CO. LTD | AA40: -81732 | AB40: -91400 | AC40: -56916 | AD40: -75792 | AE40: Local | AF40: =D40&G40 -> PNHX2299ZA/V11185
...

Sheet Sum
B1: Summary NG List
B2: No. | C2: Sloc. | D2: 45962 | G2: Total | H2: 45992 | K2: Total | L2: PIC | M2: Plan
D3: VENDOR COST | E3: PSNV COST | F3: PENDING | H3: VENDOR COST | I3: PSNV COST | J3: PENDING
B4: 1 | C4: 6185 | D4: 0 | E4: 9.86155 | F4: 0 | G4: =SUM(D4:F4) -> 9.86155 | H4: =SUMIF('NG list'!G:G,Sum!C:C,'NG list'!M:M) -> 0 | I4: =SUMIF('NG list'!G:G,Sum!C:C,'NG list'!O:O) -> 35.43105 | J4: =SUMIF('NG list'!G:G,Sum!C:C,'NG list'!Q:Q) -> 0 | K4: =SUM(H4:J4) -> 35.43105 | L4: Ms.Ha My | M4: VG01
B5: 2 | C5: 6196 | D5: 0 | E5: 28.57145 | F5: 0 | G5: =SUM(D5:F5) -> 28.57145 | H5: =SUMIF('NG list'!G:G,Sum!C:C,'NG list'!M:M) -> 0 | I5: =SUMIF('NG list'!G:G,Sum!C:C,'NG list'!O:O) -> 4.58038 | J5: =SUMIF('NG list'!G:G,Sum!C:C,'NG list'!Q:Q) -> 0 | K5: =SUM(H5:J5) -> 4.58038 | L5: Ms.Ha My | M5: VG01
B6: 3 | C6: 6197 | D6: 648.4362 | E6: 295.92726 | F6: 55.3566 | G6: =SUM(D6:F6) -> 999.72006 | H6: =SUMIF('NG list'!G:G,Sum!C:C,'NG list'!M:M) -> 218.671 | I6: =SUMIF('NG list'!G:G,Sum!C:C,'NG list'!O:O) -> 335.60615 | J6: =SUMIF('NG list'!G:G,Sum!C:C,'NG list'!Q:Q) -> 0 | K6: =SUM(H6:J6) -> 554.27715 | L6: Ms.Ha My | M6: VG01
B7: 4 | C7: 6198 | D7: 0 | E7: 26.87958 | F7: 0 | G7: =SUM(D7:F7) -> 26.87958 | H7: =SUMIF('NG list'!G:G,Sum!C:C,'NG list'!M:M) -> 0 | I7: =SUMIF('NG list'!G:G,Sum!C:C,'NG list'!O:O) -> 165.4291 | J7: =SUMIF('NG list'!G:G,Sum!C:C,'NG list'!Q:Q) -> 0 | K7: =SUM(H7:J7) -> 165.4291 | L7: Ms.Ha My | M7: VG01
B8: 5 | C8: 61S5 | D8: 0 | E8: 0 | F8: 0 | G8: =SUM(D8:F8) -> 0 | H8: =SUMIF('NG list'!G:G,Sum!C:C,'NG list'!M:M) -> 0 | I8: =SUMIF('NG list'!G:G,Sum!C:C,'NG list'!O:O) -> 2.581 | J8: =SUMIF('NG list'!G:G,Sum!C:C,'NG list'!Q:Q) -> 0 | K8: =SUM(H8:J8) -> 2.581 | L8: Ms.Ha My | M8: VG01
B9: 6 | C9: 61S7 | D9: 0 | E9: 0 | F9: 0 | G9: =SUM(D9:F9) -> 0 | H9: =SUMIF('NG list'!G:G,Sum!C:C,'NG list'!M:M) -> 0 | I9: =SUMIF('NG list'!G:G,Sum!C:C,'NG list'!O:O) -> 0 | J9: =SUMIF('NG list'!G:G,Sum!C:C,'NG list'!Q:Q) -> 0 | K9: =SUM(H9:J9) -> 0 | L9: Ms.Ha My | M9: VG01
B10: 7 | C10: 6DK7 | D10: 28.3776 | E10: 22.34963 | F10: 127.6992 | G10: =SUM(D10:F10) -> 178.42643 | H10: =SUMIF('NG list'!G:G,Sum!C:C,'NG list'!M:M) -> 0 | I10: =SUMIF('NG list'!G:G,Sum!C:C,'NG list'!O:O) -> 1.79374 | J10: =SUMIF('NG list'!G:G,Sum!C:C,'NG list'!Q:Q) -> 0 | K10: =SUM(H10:J10) -> 1.79374 | L10: Ms.Ha My | M10: VG01
B11: 8 | C11: 6JP7 | D11: 0 | E11: 0 | F11: 0 | G11: =SUM(D11:F11) -> 0 | H11: =SUMIF('NG list'!G:G,Sum!C:C,'NG list'!M:M) -> 0 | I11: =SUMIF('NG list'!G:G,Sum!C:C,'NG list'!O:O) -> 0 | J11: =SUMIF('NG list'!G:G,Sum!C:C,'NG list'!Q:Q) -> 0 | K11: =SUM(H11:J11) -> 0 | L11: Ms.Ha My | M11: VG01
B12: 9 | C12: 6193 | D12: 0 | E12: 0 | F12: 0 | G12: =SUM(D12:F12) -> 0 | H12: =SUMIF('NG list'!G:G,Sum!C:C,'NG list'!M:M) -> 0 | I12: =SUMIF('NG list'!G:G,Sum!C:C,'NG list'!O:O) -> 18.2688 | J12: =SUMIF('NG list'!G:G,Sum!C:C,'NG list'!Q:Q) -> 0 | K12: =SUM(H12:J12) -> 18.2688 | L12: Ms.Ha My | M12: VG01
B13: 10 | C13: 61T8 | D13: 0 | E13: 0 | F13: 0 | G13: =SUM(D13:F13) -> 0 | H13: =SUMIF('NG list'!G:G,Sum!C:C,'NG list'!M:M) -> 0 | I13: =SUMIF('NG list'!G:G,Sum!C:C,'NG list'!O:O) -> 0 | J13: =SUMIF('NG list'!G:G,Sum!C:C,'NG list'!Q:Q) -> 0 | K13: =SUM(H13:J13) -> 0 | L13: Ms.Ha My | M13: VG01
B14: 11 | C14: 61W5 | D14: 0 | E14: 1.22292 | F14: 0 | G14: =SUM(D14:F14) -> 1.22292 | H14: =SUMIF('NG list'!G:G,Sum!C:C,'NG list'!M:M) -> 0 | I14: =SUMIF('NG list'!G:G,Sum!C:C,'NG list'!O:O) -> 0 | J14: =SUMIF('NG list'!G:G,Sum!C:C,'NG list'!Q:Q) -> 0 | K14: =SUM(H14:J14) -> 0 | L14: Ms.Ha My | M14: VG01
B15: 12 | C15: 6M17 | D15: 0 | E15: 0 | F15: 0 | G15: =SUM(D15:F15) -> 0 | H15: =SUMIF('NG list'!G:G,Sum!C:C,'NG list'!M:M) -> 0 | I15: =SUMIF('NG list'!G:G,Sum!C:C,'NG list'!O:O) -> 0 | J15: =SUMIF('NG list'!G:G,Sum!C:C,'NG list'!Q:Q) -> 0 | K15: =SUM(H15:J15) -> 0 | L15: Ms.Ha My | M15: VG01
B16: 1 | C16: 9C85 | D16: 0 | E16: 0 | F16: 0 | G16: =SUM(D16:F16) -> 0 | H16: =SUMIF('NG list'!G:G,Sum!C:C,'NG list'!M:M) -> 0 | I16: =SUMIF('NG list'!G:G,Sum!C:C,'NG list'!O:O) -> 2.4647 | J16: =SUMIF('NG list'!G:G,Sum!C:C,'NG list'!Q:Q) -> 0 | K16: =SUM(H16:J16) -> 2.4647 | L16: Ms.Riem | M16: VE01
B17: 2 | C17: 9C93 | D17: 0 | E17: 0 | F17: 0 | G17: =SUM(D17:F17) -> 0 | H17: =SUMIF('NG list'!G:G,Sum!C:C,'NG list'!M:M) -> 0 | I17: =SUMIF('NG list'!G:G,Sum!C:C,'NG list'!O:O) -> 0 | J17: =SUMIF('NG list'!G:G,Sum!C:C,'NG list'!Q:Q) -> 0 | K17: =SUM(H17:J17) -> 0 | L17: Ms.Riem | M17: VE01
B18: 3 | C18: 9C96 | D18: 0 | E18: 0 | F18: 0 | G18: =SUM(D18:F18) -> 0 | H18: =SUMIF('NG list'!G:G,Sum!C:C,'NG list'!M:M) -> 0 | I18: =SUMIF('NG list'!G:G,Sum!C:C,'NG list'!O:O) -> 0 | J18: =SUMIF('NG list'!G:G,Sum!C:C,'NG list'!Q:Q) -> 0 | K18: =SUM(H18:J18) -> 0 | L18: Ms.Riem | M18: VE01
B19: 4 | C19: 9C97 | D19: 0 | E19: 0 | F19: 0 | G19: =SUM(D19:F19) -> 0 | H19: =SUMIF('NG list'!G:G,Sum!C:C,'NG list'!M:M) -> 0 | I19: =SUMIF('NG list'!G:G,Sum!C:C,'NG list'!O:O) -> 70.41834 | J19: =SUMIF('NG list'!G:G,Sum!C:C,'NG list'!Q:Q) -> 0 | K19: =SUM(H19:J19) -> 70.41834 | L19: Ms.Riem | M19: VE01
B20: 5 | C20: 9C98 | D20: 0 | E20: 0 | F20: 0 | G20: =SUM(D20:F20) -> 0 | H20: =SUMIF('NG list'!G:G,Sum!C:C,'NG list'!M:M) -> 0 | I20: =SUMIF('NG list'!G:G,Sum!C:C,'NG list'!O:O) -> 27.84935 | J20: =SUMIF('NG list'!G:G,Sum!C:C,'NG list'!Q:Q) -> 0 | K20: =SUM(H20:J20) -> 27.84935 | L20: Ms.Riem | M20: VE01
B21: 6 | C21: 9S85 | D21: 0 | E21: 12.75694 | F21: 0 | G21: =SUM(D21:F21) -> 12.75694 | H21: =SUMIF('NG list'!G:G,Sum!C:C,'NG list'!M:M) -> 0 | I21: =SUMIF('NG list'!G:G,Sum!C:C,'NG list'!O:O) -> 63.25082 | J21: =SUMIF('NG list'!G:G,Sum!C:C,'NG list'!Q:Q) -> 0 | K21: =SUM(H21:J21) -> 63.25082 | L21: Ms.Riem | M21: VE01
B22: 7 | C22: 9S93 | D22: 0 | E22: 32.6264 | F22: 0 | G22: =SUM(D22:F22) -> 32.6264 | H22: =SUMIF('NG list'!G:G,Sum!C:C,'NG list'!M:M) -> 0 | I22: =SUMIF('NG list'!G:G,Sum!C:C,'NG list'!O:O) -> 74.06599 | J22: =SUMIF('NG list'!G:G,Sum!C:C,'NG list'!Q:Q) -> 0 | K22: =SUM(H22:J22) -> 74.06599 | L22: Ms.Riem | M22: VE01
B23: 8 | C23: 9S96 | D23: 0 | E23: 13.18606 | F23: 0 | G23: =SUM(D23:F23) -> 13.18606 | H23: =SUMIF('NG list'!G:G,Sum!C:C,'NG list'!M:M) -> 0 | I23: =SUMIF('NG list'!G:G,Sum!C:C,'NG list'!O:O) -> 0.88795 | J23: =SUMIF('NG list'!G:G,Sum!C:C,'NG list'!Q:Q) -> 0 | K23: =SUM(H23:J23) -> 0.88795 | L23: Ms.Riem | M23: VE01
B24: 9 | C24: 9S97 | D24: 33.5905 | E24: 36.20838 | F24: 0 | G24: =SUM(D24:F24) -> 69.79888 | H24: =SUMIF('NG list'!G:G,Sum!C:C,'NG list'!M:M) -> 27.8481 | I24: =SUMIF('NG list'!G:G,Sum!C:C,'NG list'!O:O) -> 123.89429 | J24: =SUMIF('NG list'!G:G,Sum!C:C,'NG list'!Q:Q) -> 0 | K24: =SUM(H24:J24) -> 151.74239 | L24: Ms.Riem | M24: VE01
... B31: 5 | C31: 11D8 | D31: 0 | E31: 13.893 | F31: 0 | G31: =SUM(D31:F31) -> 13.893 | H31: =SUMIF('NG list'!G:G,Sum!C:C,'NG list'!M:M) -> 0 | I31: =SUMIF('NG list'!G:G,Sum!C:C,'NG list'!O:O) -> 10.7065 | J31: =SUMIF('NG list'!G:G,Sum!C:C,'NG list'!Q:Q) -> 0 | K31: =SUM(H31:J31) -> 10.7065 | L31: Ms.Riem | M31: VR01
B32: 6 | C32: 1185 | D32: 0 | E32: 36.85364 | F32: 0 | G32: =SUM(D32:F32) -> 36.85364 | H32: =SUMIF('NG list'!G:G,Sum!C:C,'NG list'!M:M) -> 0 | I32: =SUMIF('NG list'!G:G,Sum!C:C,'NG list'!O:O) -> 126.77915 | J32: =SUMIF('NG list'!G:G,Sum!C:C,'NG list'!Q:Q) -> 0 | K32: =SUM(H32:J32) -> 126.77915 | L32: Ms.Riem | M32: VR01
B33: 7 | C33: 1196 | D33: 62.12925 | E33: 54.63656 | F33: 0 | G33: =SUM(D33:F33) -> 116.76581 | H33: =SUMIF('NG list'!G:G,Sum!C:C,'NG list'!M:M) -> 9.22204 | I33: =SUMIF('NG list'!G:G,Sum!C:C,'NG list'!O:O) -> 0 | J33: =SUMIF('NG list'!G:G,Sum!C:C,'NG list'!Q:Q) -> 0 | K33: =SUM(H33:J33) -> 9.22204 | L33: Ms.Riem | M33: VR01
B34: 8 | C34: 1197 | D34: 1569.556 | E34: 120.31393 | F34: 7098.8 | G34: =SUM(D34:F34) -> 8788.6699 | H34: =SUMIF('NG list'!G:G,Sum!C:C,'NG list'!M:M) -> 68.64 | I34: =SUMIF('NG list'!G:G,Sum!C:C,'NG list'!O:O) -> 212.02773 | J34: =SUMIF('NG list'!G:G,Sum!C:C,'NG list'!Q:Q) -> 0 | K34: =SUM(H34:J34) -> 280.66773 | L34: Ms.Riem | M34: VR01
B35: 9 | C35: 1193 | D35: 0 | E35: 0 | F35: 0 | G35: =SUM(D35:F35) -> 0 | H35: =SUMIF('NG list'!G:G,Sum!C:C,'NG list'!M:M) -> 0 | I35: =SUMIF('NG list'!G:G,Sum!C:C,'NG list'!O:O) -> 0 | J35: =SUMIF('NG list'!G:G,Sum!C:C,'NG list'!Q:Q) -> 0 | K35: =SUM(H35:J35) -> 0 | L35: Ms.Riem | M35: VR01
B36: 10 | C36: 1198 | D36: 0 | E36: 35.25417 | F36: 0 | G36: =SUM(D36:F36) -> 35.25417 | H36: =SUMIF('NG list'!G:G,Sum!C:C,'NG list'!M:M) -> 0 | I36: =SUMIF('NG list'!G:G,Sum!C:C,'NG list'!O:O) -> 14.9395 | J36: =SUMIF('NG list'!G:G,Sum!C:C,'NG list'!Q:Q) -> 0 | K36: =SUM(H36:J36) -> 14.9395 | L36: Ms.Riem | M36: VR01
B37: 11 | C37: 1DK7 | D37: 12.545 | E37: 16.99351 | F37: 0 | G37: =SUM(D37:F37) -> 29.53851 | H37: =SUMIF('NG list'!G:G,Sum!C:C,'NG list'!M:M) -> 0 | I37: =SUMIF('NG list'!G:G,Sum!C:C,'NG list'!O:O) -> 20.58654 | J37: =SUMIF('NG list'!G:G,Sum!C:C,'NG list'!Q:Q) -> 0 | K37: =SUM(H37:J37) -> 20.58654 | L37: Ms.Riem | M37: VR01
B38: 1 | C38: 5185 | D38: 0 | E38: 0 | F38: 0 | G38: =SUM(D38:F38) -> 0 | H38: =SUMIF('NG list'!G:G,Sum!C:C,'NG list'!M:M) -> 0 | I38: =SUMIF('NG list'!G:G,Sum!C:C,'NG list'!O:O) -> 0 | J38: =SUMIF('NG list'!G:G,Sum!C:C,'NG list'!Q:Q) -> 0 | K38: =SUM(H38:J38) -> 0 | L38: Ms.Uyen | M38: VB01
B39: 2 | C39: 5196 | D39: 0 | E39: 0 | F39: 0 | G39: =SUM(D39:F39) -> 0 | H39: =SUMIF('NG list'!G:G,Sum!C:C,'NG list'!M:M) -> 0 | I39: =SUMIF('NG list'!G:G,Sum!C:C,'NG list'!O:O) -> 0 | J39: =SUMIF('NG list'!G:G,Sum!C:C,'NG list'!Q:Q) -> 0 | K39: =SUM(H39:J39) -> 0 | L39: Ms.Uyen | M39: VB01
B40: 3 | C40: 5197 | D40: 0 | E40: 0 | F40: 0 | G40: =SUM(D40:F40) -> 0 | H40: =SUMIF('NG list'!G:G,Sum!C:C,'NG list'!M:M) -> 0 | I40: =SUMIF('NG list'!G:G,Sum!C:C,'NG list'!O:O) -> 0 | J40: =SUMIF('NG list'!G:G,Sum!C:C,'NG list'!Q:Q) -> 0 | K40: =SUM(H40:J40) -> 0 | L40: Ms.Uyen | M40: VB01
B41: 4 | C41: 5193 | D41: 0 | E41: 0 | F41: 0 | G41: =SUM(D41:F41) -> 0 | H41: =SUMIF('NG list'!G:G,Sum!C:C,'NG list'!M:M) -> 0 | I41: =SUMIF('NG list'!G:G,Sum!C:C,'NG list'!O:O) -> 0 | J41: =SUMIF('NG list'!G:G,Sum!C:C,'NG list'!Q:Q) -> 0 | K41: =SUM(H41:J41) -> 0 | L41: Ms.Uyen | M41: VB01
B42: 5 | C42: 5198 | D42: 0 | E42: 0 | F42: 0 | G42: =SUM(D42:F42) -> 0 | H42: =SUMIF('NG list'!G:G,Sum!C:C,'NG list'!M:M) -> 0 | I42: =SUMIF('NG list'!G:G,Sum!C:C,'NG list'!O:O) -> 0 | J42: =SUMIF('NG list'!G:G,Sum!C:C,'NG list'!Q:Q) -> 0 | K42: =SUM(H42:J42) -> 0 | L42: Ms.Uyen | M42: VB01
B43: 6 | C43: 5DK7 | D43: 43.54912 | E43: 45.72988 | F43: 0 | G43: =SUM(D43:F43) -> 89.279 | H43: =SUMIF('NG list'!G:G,Sum!C:C,'NG list'!M:M) -> 0 | I43: =SUMIF('NG list'!G:G,Sum!C:C,'NG list'!O:O) -> 0 | J43: =SUMIF('NG list'!G:G,Sum!C:C,'NG list'!Q:Q) -> 0 | K43: =SUM(H43:J43) -> 0 | L43: Ms.Uyen | M43: VB01
B44: 7 | C44: 5P85 | D44: 0 | E44: 22.10136 | F44: 0 | G44: =SUM(D44:F44) -> 22.10136 | H44: =SUMIF('NG list'!G:G,Sum!C:C,'NG list'!M:M) -> 0 | I44: =SUMIF('NG list'!G:G,Sum!C:C,'NG list'!O:O) -> 0 | J44: =SUMIF('NG list'!G:G,Sum!C:C,'NG list'!Q:Q) -> 0 | K44: =SUM(H44:J44) -> 0 | L44: Ms.Uyen | M44: VB01
B45: 8 | C45: 5P96 | D45: 247.84854 | E45: 47.28564 | F45: 0 | G45: =SUM(D45:F45) -> 295.13418 | H45: =SUMIF('NG list'!G:G,Sum!C:C,'NG list'!M:M) -> 0 | I45: =SUMIF('NG list'!G:G,Sum!C:C,'NG list'!O:O) -> 0 | J45: =SUMIF('NG list'!G:G,Sum!C:C,'NG list'!Q:Q) -> 0 | K45: =SUM(H45:J45) -> 0 | L45: Ms.Uyen | M45: VB01
B46: 9 | C46: 5P97 | D46: 544.93627 | E46: 1154.8085 | F46: 2.893 | G46: =SUM(D46:F46) -> 1702.6378 | H46: =SUMIF('NG list'!G:G,Sum!C:C,'NG list'!M:M) -> 0 | I46: =SUMIF('NG list'!G:G,Sum!C:C,'NG list'!O:O) -> 0 | J46: =SUMIF('NG list'!G:G,Sum!C:C,'NG list'!Q:Q) -> 0 | K46: =SUM(H46:J46) -> 0 | L46: Ms.Uyen | M46: VB01
...
